Workbook

Sheet Project Pairs
A1: GACC | B1: WP | C1: TP | D1: FOUS | E1: FOUS CPAPD FINAL | O1: AveGrwth>2.5Ls | P1: R^2 Scaled Ls | Q1: Ave Growth over 2.5 As | R1: LF | S1: LF CPAPD FINAL | T1: AveGrwth>2.5Ls | U1: Average Growth over 2.5 As | X1: R^2 Scaled Ls | Y1: Fire within 60km of FOUS at same time? | Z1: Non FOUS burning at same time as FOUS | AA1: Ls_1st_>2.5 | AB1: Day >2.5
A2: Northern California | B2: 21 | C2: 1 | D2: Antelope 2021 | E2: =[1]Antelope_FOUS_1!O77 -> 581.95178 | G2: Y | O2: =AVERAGE([1]Antelope_FOUS_1!H4,[1]Antelope_FOUS_1!H5,[1]Antelope_FOUS_1!H6,[1]Antelope_FOUS_1!H42,[1]Antelope_FOUS_1!H43,[1]Antelope_FOUS_1!H44) -> 4.5082621 | Q2: =AVERAGE([1]Antelope_FOUS_1!J5,[1]Antelope_FOUS_1!J6,[1]Antelope_FOUS_1!J43,[1]Antelope_FOUS_1!J44) -> 5.7088706 | R2: Lava 2021 | S2: ='[2]LavaLF(17)'!P73 -> 1509.3071 | T2: =AVERAGE('[2]LavaLF(17)'!L4,'[2]LavaLF(17)'!L7) -> 6.5854196 | U2: =AVERAGE('[2]LavaLF(17)'!J7,'[2]LavaLF(17)'!J8,'[2]LavaLF(17)'!J10) -> 11.277771 | V2: lightning | W2: Y | Y2: yes | Z2: Lava | AA2: yes
A3: Northwest | B3: 22 | C3: 2 | D3: Archie Creek 2020 | E3: 348 | G3: Y | O3: =AVERAGE([3]ArchieCrk_FOUS_2!J2,[3]ArchieCrk_FOUS_2!J3) -> 8.1725289 | Q3: =AVERAGE([3]ArchieCrk_FOUS_2!I2,[3]ArchieCrk_FOUS_2!I3) -> 7.0302831 | R3: Cinder Butte 2017 | S3: ='[4]CinderButteLF(23)'!P13 -> 102.01439 | T3: =AVERAGE('[4]CinderButteLF(23)'!L2,'[4]CinderButteLF(23)'!L5) -> 3.1504849 | U3: =AVERAGE('[4]CinderButteLF(23)'!J5) -> 8.3114352 | V3: unknown | W3: N | Y3: yes | Z3: Tortolita | AA3: yes | AB3: 43989
A4: Great Basin | B4: 23 | C4: 3 | D4: Badger 2020 | E4: 201 | G4: Y | O4: =AVERAGE([5]Badger_FOUS_3!H3,[5]Badger_FOUS_3!H4,[5]Badger_FOUS_3!H5,[5]Badger_FOUS_3!H8) -> 4.2255848 | Q4: =AVERAGE([5]Badger_FOUS_3!G5,[5]Badger_FOUS_3!G8) -> 9.6120608 | R4: Black Pine 2007 | U4: =AVERAGE('[6]BlackPineLF(21)'!I4) -> 7.9000451 | W4: Y | Y4: no | Z4: no
A5: Northwest | B5: 24 | C5: 4 | D5: Beachie Creek 2020 | E5: =[7]BeachieCrk_FOUS_4!N76 -> 176.39389 | G5: Y | H5: 44 49 16 N | I5: 122 11 17 W | J5: 44059 | K5: 44100 | M5: 192843 | N5: =K5-J5 -> 41 | O5: =AVERAGE([7]BeachieCrk_FOUS_4!J25,[7]BeachieCrk_FOUS_4!J26) -> 24.414783 | Q5: =AVERAGE([7]BeachieCrk_FOUS_4!I26,[7]BeachieCrk_FOUS_4!I25) -> 34.958111 | R5: County Line 2 2015 | S5: ='[8](2)CountyLine2LF'!O23 -> 183.01665 | T5: =AVERAGE('[8](2)CountyLine2LF'!K2,'[8](2)CountyLine2LF'!K4,'[8](2)CountyLine2LF'!K6) -> 6.4054193 | U5: =AVERAGE('[8](2)CountyLine2LF'!I2,'[8](2)CountyLine2LF'!I4,'[8](2)CountyLine2LF'!I6) -> 5.6705204 | V5: human | W5: Y | Y5: yes
A6: Southwest | B6: 25 | C6: 5 | D6: Bighorn 2020 | E6: 425 | G6: Y | O6: =AVERAGE([9]Bighorn_FOUS_5!I12) -> 3.433069 | Q6: =AVERAGE([9]Bighorn_FOUS_5!H12,[9]Bighorn_FOUS_5!H15,[9]Bighorn_FOUS_5!H18,[9]Bighorn_FOUS_5!H22) -> 3.088361 | R6: Burro 2017 | S6: 399 | T6: =AVERAGE('[10]BurroLF(24)'!I4) -> 2.5384179 | U6: =AVERAGE('[10]BurroLF(24)'!G4,'[10]BurroLF(24)'!G5) -> 3.9743852 | V6: unknown | W6: N | Y6: yes | Z6: Central, Boulder | AA6: no | AC6: Both started after >2.5 day
A7: Southwest | B7: 26 | C7: 6 | D7: Black Fire 2022 | E7: =[11]Black_FOUS_6!T49 -> 183.30422 | F7: human | H7: 33 12 13 N | I7: 108 3 33 W | J7: 44694 | K7: 44731 | M7: 325111 | N7: =K7-J7 -> 37 | O7: =AVERAGE([11]Black_FOUS_6!P3,[11]Black_FOUS_6!P4) -> 4.312821 | Q7: =AVERAGE([11]Black_FOUS_6!O5) -> 5.5169529 | R7: Bear Trap 2022 | S7: ='[12](3)Bear TrapLF'!AB40 -> 497.0569 | T7: 0 | U7: =0 -> 0 | V7: undetermined | Y7: yes
A8: Southern California | B8: 27 | C8: 7 | D8: Bobcat 2020 | E8: =[13]Bobcat_FOUS_7!L55 -> 988.22854 | G8: Y | O8: =AVERAGE([13]Bobcat_FOUS_7!H2,[13]Bobcat_FOUS_7!H4,[13]Bobcat_FOUS_7!H15) -> #REF! | Q8: =AVERAGE([13]Bobcat_FOUS_7!H2,[13]Bobcat_FOUS_7!H4,[13]Bobcat_FOUS_7!H15,) -> #REF! | R8: Dome 2020 | S8: ='[14]DomeLF(12)'!O11 -> 58.17771 | T8: 0 | U8: =AVERAGE('[14]DomeLF(12)'!I4) -> 5.0664387 | V8: lightning | W8: N | Y8: no | Z8: no
A9: Northwest | B9: 28 | C9: 8 | D9: Bootleg 2021 | E9: 277 | G9: Y | O9: =AVERAGE('[15]BootlegFOUS(28)'!K2,'[15]BootlegFOUS(28)'!K4,'[15]BootlegFOUS(28)'!K6) -> 2.9960054 | Q9: =AVERAGE('[15]BootlegFOUS(28)'!I6,'[15]BootlegFOUS(28)'!I12) -> 5.7765366 | R9: Watson Creek 2018 | S9: 381 | T9: =AVERAGE('[16]WatsonCreekLF(28)'!I3,'[16]WatsonCreekLF(28)'!I4,'[16]WatsonCreekLF(28)'!I5,'[16]WatsonCreekLF(28)'!I6) -> 4.1286316 | U9: =AVERAGE('[16]WatsonCreekLF(28)'!G4,'[16]WatsonCreekLF(28)'!G6,'[16]WatsonCreekLF(28)'!G7,'[16]WatsonCreekLF(28)'!G10) -> 3.3413287 | V9: human | W9: N | Y9: yes
A10: Southwest | B10: 29 | C10: 9 | D10: Bush 2020 | E10: 69 | G10: Y | O10: =AVERAGE('[17]BushFOUS(19)'!I2,'[17]BushFOUS(19)'!I3) -> 3.4852948 | Q10: ='[17]BushFOUS(19)'!H7 -> 3.0366545 | R10: Juniper 2016 | S10: 467 | T10: =AVERAGE('[18]JuniperLF(19)'!H6) -> 2.6475686 | U10: =AVERAGE('[18]JuniperLF(19)'!F17) -> 4.8881852 | V10: lightning | W10: N | Y10: yes
A11: Northern Califormia | B11: 30 | C11: 10 | D11: Caldor 2021 | E11: 1399 | G11: Y | O11: =AVERAGE('[19]CaldorFOUS(22)'!L3,'[19]CaldorFOUS(22)'!L4) -> 6.5612643 | Q11: =AVERAGE('[19]CaldorFOUS(22)'!K4,'[19]CaldorFOUS(22)'!K16,) -> 7.0365661 | R11: Butte 2015 | S11: ='[20]ButteLF(22)'!P24 -> 1313.8521 | T11: =AVERAGE('[20]ButteLF(22)'!L2,'[20]ButteLF(22)'!L3,'[20]ButteLF(22)'!L4) -> #REF! | U11: =AVERAGE('[20]ButteLF(22)'!L2,'[20]ButteLF(22)'!L3,'[20]ButteLF(22)'!L4) -> #REF! | V11: unknown | W11: Y | Y11: no | Z11: no
A12: Rocky Mountain | B12: 31 | C12: 11 | D12: Cameron Peak 2020 | E12: 731 | G12: Y | O12: =AVERAGE('[21]CameronPeakFOUS(29)'!J2,'[21]CameronPeakFOUS(29)'!J4,'[21]CameronPeakFOUS(29)'!J24,'[21]CameronPeakFOUS(29)'!J25,'[21]CameronPeakFOUS(29)'!J45,'[21]CameronPeakFOUS(29)'!J65,'[21]CameronPeakFOUS(29)'!J66) -> 4.7203712 | Q12: =AVERAGE('[21]CameronPeakFOUS(29)'!I25,'[21]CameronPeakFOUS(29)'!I26,'[21]CameronPeakFOUS(29)'!I27) -> 13.884024 | R12: High Park 2012 | S12: 49 | T12: 6.2 | U12: =AVERAGE('[22]HighParkLF(29)'!E3,'[22]HighParkLF(29)'!E4,'[22]HighParkLF(29)'!E16) -> 4.9434872 | V12: lightning | W12: Y | Y12: yes, 2 plus 2 FOUS
A13: Northwest | B13: 32 | C13: 12 | D13: Cougar Peak 2021 | E13: ='[23]CougarPeakFOUS(15)'!M29 -> 320.22394 | G13: N | O13: =AVERAGE('[23]CougarPeakFOUS(15)'!I3,'[23]CougarPeakFOUS(15)'!I4) -> 5.4499517 | Q13: =AVERAGE('[23]CougarPeakFOUS(15)'!H3,'[23]CougarPeakFOUS(15)'!H4) -> 12.510032 | R13: Brattain 2020 | S13: ='[24]BrattainLF(15)'!N24 -> 214.48731 | T13: =AVERAGE('[24]BrattainLF(15)'!J8) -> 3.5033504 | U13: =AVERAGE('[24]BrattainLF(15)'!I8) -> 7.0014327 | V13: human | W13: Y | Y13: no | Z13: no
A14: Southern California | B14: 33 | C14: 13 | D14: Creek 2020 | E14: ='[25](4)CreekFOUS'!O83 -> 581.35938 | F14: undetermined | G14: Y | H14: 37 12 4 N | I14: 119 16 18 W | J14: 44078 | K14: 44132 | M14: 374770 | N14: =K14-J14 -> 54 | O14: =AVERAGE('[25](4)CreekFOUS'!K3,'[25](4)CreekFOUS'!K4,'[25](4)CreekFOUS'!K5,'[25](4)CreekFOUS'!K6) -> 8.9757632 | Q14: =AVERAGE('[25](4)CreekFOUS'!J3,'[25](4)CreekFOUS'!J4,'[25](4)CreekFOUS'!J5,'[25](4)CreekFOUS'!J6,'[25](4)CreekFOUS'!J13,'[25](4)CreekFOUS'!J16,) -> 6.2097324 | R14: Donnell 2018 | S14: ='[26](4)DonnellLF'!R43 -> 1099.6144 | T14: =AVERAGE('[26](4)DonnellLF'!N3,'[26](4)DonnellLF'!N5,'[26](4)DonnellLF'!N6,'[26](4)DonnellLF'!N7,'[26](4)DonnellLF'!N9) -> 3.8435772 | U14: =AVERAGE('[26](4)DonnellLF'!M6,'[26](4)DonnellLF'!M7,'[26](4)DonnellLF'!M9,'[26](4)DonnellLF'!M10,'[26](4)DonnellLF'!M12,'[26](4)DonnellLF'!M22) -> 4.2604938 | V14: unknown | W14: N | Y14: yes
A15: Northern California | B15: 34 | C15: 14 | D15: Dixie 2021 | E15: ='[27]DixieFOUS(7)'!T106 -> 748.2317 | G15: Y | O15: =AVERAGE('[27]DixieFOUS(7)'!P3,'[27]DixieFOUS(7)'!P4,'[27]DixieFOUS(7)'!P9,'[27]DixieFOUS(7)'!P10,'[27]DixieFOUS(7)'!P12,'[27]DixieFOUS(7)'!P13) -> 4.616172 | Q15: =AVERAGE('[27]DixieFOUS(7)'!O9,'[27]DixieFOUS(7)'!O12,'[27]DixieFOUS(7)'!O13,'[27]DixieFOUS(7)'!O25,'[27]DixieFOUS(7)'!O28,'[27]DixieFOUS(7)'!O38,'[27]DixieFOUS(7)'!O39,'[27]DixieFOUS(7)'!O40,'[27]DixieFOUS(7)'!O51,'[27]DixieFOUS(7)'!O52,) -> 5.2069689 | R15: Walker 2019 | S15: ='[28]WalkerLF(7)'!T23 -> 759.43823 | T15: =AVERAGE('[28]WalkerLF(7)'!P5) -> 6.061323 | U15: =AVERAGE('[28]WalkerLF(7)'!N5,'[28]WalkerLF(7)'!N6) -> 7.080263 | V15: unknown | W15: Y | Y15: yes
A16: Southern California | B16: 35 | C16: 15 | D16: Dolan 2020 | E16: 659 | G16: Y | O16: =AVERAGE('[29]DolanFOUS(30)'!I3,'[29]DolanFOUS(30)'!I22,'[29]DolanFOUS(30)'!I23) -> 6.5290048 | Q16: =AVERAGE('[29]DolanFOUS(30)'!H22,'[29]DolanFOUS(30)'!H23,'[29]DolanFOUS(30)'!H24) -> 15.954326 | R16: Chimney 2016 | S16: ='[30]ChimneyLF(30)'!M25 -> 1634.2559 | T16: =AVERAGE('[30]ChimneyLF(30)'!I3,'[30]ChimneyLF(30)'!I4,'[30]ChimneyLF(30)'!I5,'[30]ChimneyLF(30)'!I6) -> 4.1286316 | U16: =AVERAGE('[30]ChimneyLF(30)'!G4,'[30]ChimneyLF(30)'!G6,'[30]ChimneyLF(30)'!G7,'[30]ChimneyLF(30)'!G10) -> 3.2150744 | V16: human | W16: Y | Y16: yes
A17: Rocky Mountain | B17: 36 | C17: 16 | D17: East Troublesome 2020 | E17: 93 | G17: Y | O17: =AVERAGE('[31]EastTroublesomeFOUS(18)'!I3) -> 3.0825435 | Q17: =AVERAGE('[31]EastTroublesomeFOUS(18)'!H9,'[31]EastTroublesomeFOUS(18)'!H10) -> 13.262775 | R17: Beaver Creek 2016 | S17: 996 | T17: =AVERAGE('[32]BeaverCreekLF(18)'!I2,'[32]BeaverCreekLF(18)'!I4,'[32]BeaverCreekLF(18)'!I5,'[32]BeaverCreekLF(18)'!I10,'[32]BeaverCreekLF(18)'!I11,'[32]BeaverCreekLF(18)'!I12,'[32]BeaverCreekLF(18)'!I22,'[32]BeaverCreekLF(18)'!I23,'[32]BeaverCreekLF(18)'!I30,'[32]BeaverCreekLF(18)'!I41) -> 6.6199271 | U17: =AVERAGE('[32]BeaverCreekLF(18)'!H4,'[32]BeaverCreekLF(18)'!H5,'[32]BeaverCreekLF(18)'!H10,'[32]BeaverCreekLF(18)'!H11,'[32]BeaverCreekLF(18)'!H12,'[32]BeaverCreekLF(18)'!H22,'[32]BeaverCreekLF(18)'!H23,'[32]BeaverCreekLF(18)'!H41) -> 6.4688468 | V17: unknown | W17: N | Y17: yes
A18: Northwest | B18: 37 | C18: 17 | D18: Holiday Farm 2020 | E18: 192 | G18: Y | O18: =AVERAGE('[33]HolidayFarmFOUS(26)'!J2,'[33]HolidayFarmFOUS(26)'!J3) -> 5.8559023 | Q18: =AVERAGE('[33]HolidayFarmFOUS(26)'!I2,'[33]HolidayFarmFOUS(26)'!I3,'[33]HolidayFarmFOUS(26)'!I4) -> 13.653574 | R18: Pole Creek 2012 | S18: ='[34]PoleCreekLF(26)'!O31 -> 848.85154 | T18: =AVERAGE('[34]PoleCreekLF(26)'!K2,'[34]PoleCreekLF(26)'!K3,'[34]PoleCreekLF(26)'!K8) -> 3.4337919 | U18: =AVERAGE('[34]PoleCreekLF(26)'!I8) -> 8.9568949 | V18: unknown | W18: N | Y18: no | Z18: no
A19: Northwest | B19: 38 | C19: 18 | D19: Lionshead 2020 | E19: 348 | G19: Y | O19: =AVERAGE('[35]LionsheadFOUS(27)'!I23,'[35]LionsheadFOUS(27)'!I24,'[35]LionsheadFOUS(27)'!I28) -> 8.5289723 | Q19: =AVERAGE('[35]LionsheadFOUS(27)'!H23,'[35]LionsheadFOUS(27)'!H24,'[35]LionsheadFOUS(27)'!H28,'[35]LionsheadFOUS(27)'!H29) -> 13.381985 | R19: Black Rock 2014 | S19: 16 | T19: =AVERAGE('[36]BlackRockLF(27)'!J7) -> 9.8911911 | U19: =AVERAGE('[36]BlackRockLF(27)'!H7) -> 10.511269 | V19: unknown | W19: Y | Y19: yes, 3 plus 2 FOUS
A20: Northern California | B20: 39 | C20: 19 | D20: McFarland 2021 | E20: 418 | G20: Y | O20: =AVERAGE('[37]McFarlandFOUS(25)'!G5,'[37]McFarlandFOUS(25)'!G6,'[37]McFarlandFOUS(25)'!G20) -> 3.7813411 | Q20: =AVERAGE('[37]McFarlandFOUS(25)'!F20) -> 17.23032 | R20: Zogg 2020 | S20: ='[38]ZoggLF(25)'!O18 -> 629.75874 | T20: =AVERAGE('[38]ZoggLF(25)'!K2,'[38]ZoggLF(25)'!K3) -> 4.0954029 | U20: =AVERAGE('[38]ZoggLF(25)'!I3,'[38]ZoggLF(25)'!I4) -> 6.5030175 | V20: unknown | W20: Y | Y20: no | Z20: no
A21: Northern California | B21: 40 | C21: 20 | D21: Monument 2021 | E21: ='[39](6)MonumentFOUS'!N89 -> 829.80693 | G21: Y | H21: 40 45 8 N | I21: 123 20 12 W | J21: 44407 | K21: 44460 | M21: 219254 | N21: =K21-J21 -> 53 | O21: =AVERAGE('[39](6)MonumentFOUS'!J4,'[39](6)MonumentFOUS'!J5,'[39](6)MonumentFOUS'!J6,'[39](6)MonumentFOUS'!J7,'[39](6)MonumentFOUS'!J8,'[39](6)MonumentFOUS'!J9,'[39](6)MonumentFOUS'!J20,'[39](6)MonumentFOUS'!J19,) -> 3.0070702 | Q21: =AVERAGE('[39](6)MonumentFOUS'!I9,'[39](6)MonumentFOUS'!I19,'[39](6)MonumentFOUS'!I20) -> 5.9507001 | R21: Delta 2018 | S21: ='[40](6)DeltaLF'!P32 -> 1030.1449 | T21: =AVERAGE('[40](6)DeltaLF'!L3) -> 6.3585579 | U21: =AVERAGE('[40](6)DeltaLF'!J2,'[40](6)DeltaLF'!J4,'[40](6)DeltaLF'!J5,'[40](6)DeltaLF'!J7,'[40](6)DeltaLF'!J8) -> 4.8038224 | V21: human | W21: Y | Y21: yes, 3 plus 1 FOUS
A22: Great Basin | B22: 41 | C22: 21 | D22: Moose 2022 | E22: ='[41]MooseFOUS(13)'!O111 -> 754.19531 | F22: human | G22: Y | O22: =AVERAGE('[41]MooseFOUS(13)'!K2,'[41]MooseFOUS(13)'!K3,'[41]MooseFOUS(13)'!K4,'[41]MooseFOUS(13)'!K5,'[41]MooseFOUS(13)'!K6,'[41]MooseFOUS(13)'!K8,'[41]MooseFOUS(13)'!K7,'[41]MooseFOUS(13)'!K15,'[41]MooseFOUS(13)'!K17) -> 5.9269046 | Q22: =AVERAGE('[41]MooseFOUS(13)'!J3,'[41]MooseFOUS(13)'!J4,'[41]MooseFOUS(13)'!J5,'[41]MooseFOUS(13)'!J6,'[41]MooseFOUS(13)'!J7,'[41]MooseFOUS(13)'!J8,'[41]MooseFOUS(13)'!J9,'[41]MooseFOUS(13)'!J15,'[41]MooseFOUS(13)'!J16,'[41]MooseFOUS(13)'!J18,'[41]MooseFOUS(13)'!J20,'[41]MooseFOUS(13)'!J33,'[41]MooseFOUS(13)'!J34,) -> 3.5662938 | R22: Trail Creek 2021 | T22: =AVERAGE('[42]TrailCreekLF(13)'!I3,'[42]TrailCreekLF(13)'!I5,'[42]TrailCreekLF(13)'!I6,'[42]TrailCreekLF(13)'!I7,'[42]TrailCreekLF(13)'!I10,'[42]TrailCreekLF(13)'!I11,'[42]TrailCreekLF(13)'!I12,'[42]TrailCreekLF(13)'!I19) -> 5.7568083 | U22: =AVERAGE('[42]TrailCreekLF(13)'!G6,'[42]TrailCreekLF(13)'!G7,'[42]TrailCreekLF(13)'!G10,'[42]TrailCreekLF(13)'!G11,'[42]TrailCreekLF(13)'!G12,'[42]TrailCreekLF(13)'!G19,'[42]TrailCreekLF(13)'!G20) -> 5.2791995 | W22: N | Y22: yes, 4
A23: Rocky Mountain | B23: 42 | C23: 22 | D23: Mullen 2020 | E23: ='[43]MullenFOUS(14)'!M47 -> 274.31085 | F23: undetermined | G23: Y | O23: =AVERAGE('[43]MullenFOUS(14)'!H2,'[43]MullenFOUS(14)'!H8,'[43]MullenFOUS(14)'!H9,'[43]MullenFOUS(14)'!H13) -> 4.6028908 | Q23: =AVERAGE('[43]MullenFOUS(14)'!G9,'[43]MullenFOUS(14)'!G10,'[43]MullenFOUS(14)'!G13,'[43]MullenFOUS(14)'!G14,) -> 4.5029433 | R23: Ryan 2018 | S23: ='[44]RyanLF(14)'!M28 -> 333.8493 | T23: =AVERAGE('[44]RyanLF(14)'!I3,'[44]RyanLF(14)'!I9,'[44]RyanLF(14)'!I10) -> 3.7200371 | U23: =AVERAGE('[44]RyanLF(14)'!G9,'[44]RyanLF(14)'!G10) -> 4.9540446 | V23: undetermined | W23: N | Y23: no | Z23: no
A24: Rocky Mountain | B24: 43 | C24: 23 | D24: Pine Gulch 2020 | E24: ='[45]PineGulchFOUS(10)'!L55 -> 288.12592 | F24: lightning | G24: Y | O24: =AVERAGE('[45]PineGulchFOUS(10)'!H7,'[45]PineGulchFOUS(10)'!H13,'[45]PineGulchFOUS(10)'!H14,'[45]PineGulchFOUS(10)'!H20) -> 2.8360135 | Q24: =AVERAGE('[45]PineGulchFOUS(10)'!G13,'[45]PineGulchFOUS(10)'!G14) -> 6.0779169 | R24: Bull Draw 2018 | S24: ='[46]BullDrawLF(10)'!L76 -> 392.19534 | T24: =AVERAGE('[46]BullDrawLF(10)'!H13) -> 3.9569004 | U24: =AVERAGE('[46]BullDrawLF(10)'!H13) -> 3.9569004 | V24: unknown | W24: N | Y24: no | Z24: no
A25: Northern Rockies | B25: 44 | C25: 24 | D25: Richard Springs 2021 | E25: ='[47]RichardSpringFOUS(9)'!O15 -> 42.949454 | F25: undetermined | G25: Y | O25: =AVERAGE('[47]RichardSpringFOUS(9)'!K4) -> 3.5072805 | Q25: =AVERAGE('[47]RichardSpringFOUS(9)'!J4) -> 8.7758312 | R25: Sarpy 2020 | S25: ='[48]SarpyLF(9)'!R11 -> 20.901993 | T25: =AVERAGE('[48]SarpyLF(9)'!I4) -> 4.7361547 | U25: =AVERAGE('[48]SarpyLF(9)'!G4) -> 8.91194 | V25: unknown | W25: N | Y25: yes
A26: Northwest | B26: 45 | C26: 25 | D26: Riverside 2020 | E26: 170 | G26: Y | O26: =AVERAGE(#REF!,#REF!) -> #REF! | R26: Nena Springs 2017 | S26: ='[49]NenaSpringsLF(16)'!O24 -> 159.38991 | T26: =AVERAGE('[49]NenaSpringsLF(16)'!K3) -> 5.4395144 | U26: =0 -> 0 | V26: human | W26: Y | Y26: yes
A27: Northwest | B27: 46 | C27: 26 | D27: Schneider Springs 2021 | E27: 568 | G27: Y | O27: =AVERAGE('[50]SchneiderSpringsFOUS(20)'!K2,'[50]SchneiderSpringsFOUS(20)'!K9,'[50]SchneiderSpringsFOUS(20)'!K13,'[50]SchneiderSpringsFOUS(20)'!K15,'[50]SchneiderSpringsFOUS(20)'!K16) -> 6.1842196 | Q27: =AVERAGE('[50]SchneiderSpringsFOUS(20)'!J9,'[50]SchneiderSpringsFOUS(20)'!J13,'[50]SchneiderSpringsFOUS(20)'!J15,'[50]SchneiderSpringsFOUS(20)'!J16,) -> 4.7259041 | R27: Jolly Mountain 2017 | S27: ='[51]JollyMountainLF(20)'!AE57 -> 825.56782 | T27: =AVERAGE('[51]JollyMountainLF(20)'!AA2,'[51]JollyMountainLF(20)'!AA20,'[51]JollyMountainLF(20)'!AA23,'[51]JollyMountainLF(20)'!AA24) -> 2.7487801 | U27: =AVERAGE('[51]JollyMountainLF(20)'!Y23,'[51]JollyMountainLF(20)'!Y24,'[51]JollyMountainLF(20)'!Y25,'[51]JollyMountainLF(20)'!Y37) -> 4.5889481 | V27: unknown | W27: Y | Y27: yes, but landscape differences, W and E of Cascade crest
A28: Northern California | B28: 47 | C28: 27 | D28: Slater 2020 | E28: ='[52](1)SlaterFOUS'!M58 -> 375.83965 | G28: Y | H28: 41 51 29 N | I28: 123 21 13 W | J28: 44082 | K28: 44138 | M28: 157270 | N28: =K28-J28 -> 56 | O28: =AVERAGE('[52](1)SlaterFOUS'!I2,'[52](1)SlaterFOUS'!I3,'[52](1)SlaterFOUS'!I4,) -> 12.421189 | Q28: =AVERAGE('[52](1)SlaterFOUS'!H4,'[52](1)SlaterFOUS'!H3,'[52](1)SlaterFOUS'!H2) -> 17.728556 | R28: McKinney 2022 | S28: ='[53](1)McKinneyLF'!T102 -> 1605.9729 | T28: =AVERAGE('[53](1)McKinneyLF'!P3,'[53](1)McKinneyLF'!P4) -> 11.566781 | U28: =AVERAGE('[53](1)McKinneyLF'!N3,'[53](1)McKinneyLF'!N4) -> 43.086817 | V28: undetermined | Y28: yes
A29: Southwest | B29: 48 | C29: 28 | D29: Telegraph 2021 | E29: ='[54]TelegraphFOUS(11)'!N31 -> 227.70716 | G29: Y | O29: =AVERAGE('[54]TelegraphFOUS(11)'!J2,'[54]TelegraphFOUS(11)'!J3,'[54]TelegraphFOUS(11)'!J11) -> 3.0148069 | Q29: =AVERAGE('[54]TelegraphFOUS(11)'!I4,) -> 1.9981743 | R29: Mescal 2021 | S29: ='[55]MescalLF(11)'!M18 -> 188.98169 | T29: =AVERAGE('[55]MescalLF(11)'!I5) -> 4.5840298 | U29: =AVERAGE('[55]MescalLF(11)'!G5) -> 5.2317647 | V29: undetermined | W29: Y | Y29: yes
A30: Northwest | B30: 49 | C30: 29 | D30: Whitney 2020 | E30: ='[56](5)WhitneyFOUS'!N10 -> 29.6342 | F30: undetermined | G30: Y | H30: 47 42 26 N | I30: 118 15 37 W | J30: 44082 | K30: 44088 | M30: 127430 | N30: =K30-J30 -> 6 | O30: =AVERAGE('[56](5)WhitneyFOUS'!J2) -> 7.1897631 | Q30: ='[56](5)WhitneyFOUS'!I2 -> 6.4615868 | R30: Williams Flats 2019 | S30: ='[57](5)WilliamsFlatLF'!P25 -> 509.31158 | T30: =AVERAGE('[57](5)WilliamsFlatLF'!L3,'[57](5)WilliamsFlatLF'!L7) -> 5.0915042 | U30: =AVERAGE('[57](5)WilliamsFlatLF'!J4,'[57](5)WilliamsFlatLF'!J8,'[57](5)WilliamsFlatLF'!J9) -> 4.9872654 | V30: unknown | W30: N | Y30: yes
A31: Great Basin | B31: 50 | C31: 30 | D31: Woodhead 2020 | E31: ='[58]WoodheadFOUS(8)'!S40 -> 132.95272 | G31: Y | O31: =AVERAGE('[58]WoodheadFOUS(8)'!O3) -> 12.752305 | Q31: =AVERAGE('[58]WoodheadFOUS(8)'!N3,'[58]WoodheadFOUS(8)'!N9,'[58]WoodheadFOUS(8)'!N5) -> 8.6979734 | R31: Mesa 2018 | S31: ='[59]MesaLF(8)'!T32 -> 522.24593 | T31: =AVERAGE('[59]MesaLF(8)'!P2,'[59]MesaLF(8)'!P3) -> 3.9844241 | U31: =AVERAGE('[59]MesaLF(8)'!N2,'[59]MesaLF(8)'!N3,'[59]MesaLF(8)'!N4) -> 7.6124216 | V31: human | W31: N | Y31: no | Z31: no
D34: Mean | E34: =AVERAGE(E4:E33) -> 410.83085 | O34: =AVERAGE(O4:O33) -> #REF! | Q34: =AVERAGE(Q4:Q32) -> #REF! | S34: =AVERAGE(S4:S33) -> 582.11811 | T34: =AVERAGE(T2:T33) -> #REF!
D36: Median | E36: =MEDIAN(E4:E33) -> 304.17493 | F36: =MEDIAN(F4:F33) -> #NUM! | G36: =MEDIAN(G4:G33) -> #NUM! | H36: =MEDIAN(H4:H33) -> #NUM! | I36: =MEDIAN(I4:I33) -> #NUM! | J36: =MEDIAN(J4:J33) -> 44082 | K36: =MEDIAN(K4:K33) -> 44135 | L36: =MEDIAN(L4:L33) -> #NUM! | ... O36: =MEDIAN(O4:O33) -> #REF! | S36: =MEDIAN(S4:S33) -> 482.02845 | T36: =MEDIAN(T2:T33) -> #REF!
T43: =AVERAGE(T4:T32) -> #REF! | U43: =AVERAGE(U4:U32) -> #REF!
V45: Y = IN WUI | W45: =14/28 -> 0.5

Sheet Inflation Rates by Year
A1: Year | B1: CPI Deflator (annual %) | C1: 2021-22 | D1: 2020-22 | E1: 2019-22 | F1: 2018-22 | G1: 2017-22 | H1: 2016-22 | I1: 2015-22 | J1: 2014-22 | K1: 2013-22 | L1: 2012-22 | M1: 2011-22 | N1: 2010-22 | O1: 2009-22 | P1: 2008-22 | Q1: 2007-22
A2: 2022 | B2: 0.08 | C2: =(1+B3)*(1+B2) -> 1.13076 | D2: =C2*(1+B4) -> 1.1443291 | E2: =D2*(1+B5) -> 1.164927 | F2: =E2*(1+B6) -> 1.1928853 | G2: =F2*(1+B7) -> 1.2179359 | H2: =G2*(1+B8) -> 1.2337691 | I2: =H2*(1+B9) -> 1.2461067 | J2: =I2*(1+B10) -> 1.2660444 | K2: =J2*(1+B11) -> 1.2850351 | L2: =K2*(1+B12) -> 1.3120209
A3: 2021 | B3: 0.047
A4: 2020 | B4: 0.012
A5: 2019 | B5: 0.018
A6: 2018 | B6: 0.024
A7: 2017 | B7: 0.021
A8: 2016 | B8: 0.013
A9: 2015 | B9: 0.01
A10: 2014 | B10: 0.016
A11: 2013 | B11: 0.015
A12: 2012 | B12: 0.021

Sheet XLFCandidates
A1: XLF | B1: LF CPAPD FINAL
A3: McCash 2021 | B3: 635
A5: North Star 2015 | B5: 257
A7: Johnson 2021 | B7: 95
A9: Rough 2015 | B9: 994
A11: Grass Valley 2018 | B11: 14
A13: Carr 2018 | B13: 825
A15: Camp 2018 | B15: 800
A17: Boundary 2021 | B17: 153
A19: Sartin Draw 2017 | B19: 17
A21: Spring Creek 2018 | B21: 353
A23: Woodbury 2019 | B23: 188
A25: Millard 2006
A27: Highline 2017 | B27: 37
A29: Arapaho 2012
A31: Barry Point 2012
A33: Diamond Creek 2017 | B33: 140
A35: Caldwell 2020 | B35: 488
A37: East Fork 2020 | B37: 466
A39: Rafael 2021 | B39: 159
A41: Evan's Canyon 2020 | B41: 169
A43: Goose Creek 2018 | B43: 70
A45: Mosquito 2022 | B45: 2358
A47: Boxcar 0410 RN 2018 | B47: 39
A49: Horseshoe 2 2011
A51: Ranch 2018
A55: Buzzard 2014
A57: Klondike 2018 | B57: 710
A59: Four County 2021
A61: Soberanes 2016 | B61: 2451

Sheet DryGulchLF(39)
A1: Date | B1: Fire Day | C1: Cause | D1: Acres | E1: Cost | F1: growth | G1: As | H1: Ls | I1: Best | J1: ICS 209 Cost | K1: Real Cost (Adjusted for Inflation) | L1: Cost per day per acre
A2: 07-05-17 | B2: 1 | C2: Unknown | D2: 64000 | E2: 300000 | F2: =I2-0 -> 64000 | G2: =$B$2/$I$2*(F2) -> 1 | H2: =$B$2/SQRT($I$2)*(SQRT(I2)-SQRT(0)) -> 1 | I2: =D2 -> 64000 | J2: =E2 -> 300000 | K2: =J2*'Inflation Rates by Year'!$C$2 -> 339228 | L2: =K2/I2 -> 5.3004375
A3: 07-07-17 | B3: 2 | C3: Unknown | D3: 64000 | E3: 800000 | F3: =I3-I2 -> 0 | G3: =$B$2/$I$2*(F3) -> 0 | H3: =$B$2/SQRT($I$2)*(SQRT(I3)-SQRT(I2)) -> 0 | I3: =D3 -> 64000 | J3: =E3 -> 800000 | K3: =J3*'Inflation Rates by Year'!$C$2 -> 904608 | L3: =K3/I3 -> 14.1345
A4: 07-08-17 | B4: 3 | C4: Unknown | D4: 64000 | E4: 1500000 | F4: =I4-I3 -> 0 | G4: =$B$2/$I$2*(F4) -> 0 | H4: =$B$2/SQRT($I$2)*(SQRT(I4)-SQRT(I3)) -> 0 | I4: =D4 -> 64000 | J4: =E4 -> 1500000 | K4: =J4*'Inflation Rates by Year'!$C$2 -> 1696140 | L4: =K4/I4 -> 26.502188
A5: 07-09-17 | B5: 4 | C5: Unknown | D5: 64000 | E5: 1700000 | F5: =I5-I4 -> 0 | G5: =$B$2/$I$2*(F5) -> 0 | H5: =$B$2/SQRT($I$2)*(SQRT(I5)-SQRT(I4)) -> 0 | I5: =D5 -> 64000 | J5: =E5 -> 1700000 | K5: =J5*'Inflation Rates by Year'!$C$2 -> 1922292 | L5: =K5/I5 -> 30.035812
A6: 07-10-17 | B6: 5 | C6: Unknown | D6: 64000 | E6: 1750000 | F6: =I6-I5 -> 0 | G6: =$B$2/$I$2*(F6) -> 0 | H6: =$B$2/SQRT($I$2)*(SQRT(I6)-SQRT(I5)) -> 0 | I6: =D6 -> 64000 | J6: =E6 -> 1750000 | K6: =J6*'Inflation Rates by Year'!$C$2 -> 1978830 | L6: =K6/I6 -> 30.919219
A7: 07-11-17 | B7: 6 | C7: Unknown | D7: 64000 | E7: 2700000 | F7: =I7-I6 -> 0 | G7: =$B$2/$I$2*(F7) -> 0 | H7: =$B$2/SQRT($I$2)*(SQRT(I7)-SQRT(I6)) -> 0 | I7: =D7 -> 64000 | J7: =E7 -> 2700000 | K7: =J7*'Inflation Rates by Year'!$C$2 -> 3053052 | L7: =K7/I7 -> 47.703938

Sheet CubCreek2LF(38)
A1: Date | B1: Fire Day | C1: Cause | D1: Acres | E1: Cost | F1: growth | G1: As | H1: Ls | I1: Best | J1: ICS 209 Cost | K1: Real Cost (Adjusted for Inflation) | L1: Cost per day per acre
A2: 07-16-21 | B2: 1 | C2: Undetermined | D2: 2000 | E2: 300000 | F2: =I2-0 -> 2000 | G2: =$B$53/$I$53*(F2) -> 1.481777 | H2: =$B$53/SQRT($I$53)*(SQRT(I2)-SQRT(0)) -> 8.7779499 | I2: =D2 -> 2000 | J2: =E2 -> 300000 | K2: =J2*'Inflation Rates by Year'!$C$2 -> 339228 | L2: =K2/I2 -> 169.614
A3: 07-17-21 | B3: 2 | C3: Undetermined | D3: 1528 | E3: 500000 | F3: =I3-I2 -> -472 | G3: =$B$53/$I$53*(F3) -> -0.34969937 | H3: =$B$53/SQRT($I$53)*(SQRT(I3)-SQRT(I2)) -> -1.105399 | I3: =D3 -> 1528 | J3: =E3 -> 500000 | K3: =J3*'Inflation Rates by Year'!$C$2 -> 565380 | L3: =K3/I3 -> 370.01309
A4: 07-18-21 | B4: 3 | C4: Undetermined | D4: 8255 | E4: 1450000 | F4: =I4-I3 -> 6727 | G4: =$B$53/$I$53*(F4) -> 4.9839569 | H4: =$B$53/SQRT($I$53)*(SQRT(I4)-SQRT(I3)) -> 10.160951 | I4: =D4 -> 8255 | J4: =E4 -> 1450000 | K4: =J4*'Inflation Rates by Year'!$C$2 -> 1639602 | L4: =K4/I4 -> 198.61926
A5: 07-19-21 | B5: 4 | C5: Undetermined | D5: 32473 | E5: 1500000 | F5: =I5-I4 -> 24218 | G5: =$B$53/$I$53*(F5) -> 17.942838 | H5: =$B$53/SQRT($I$53)*(SQRT(I5)-SQRT(I4)) -> 17.536844 | I5: =D5 -> 32473 | J5: =E5 -> 1500000 | K5: =J5*'Inflation Rates by Year'!$C$2 -> 1696140 | L5: =K5/I5 -> 52.232316
A6: 07-20-21 | B6: 5 | C6: Undetermined | D6: 35134 | E6: 3100000 | F6: =I6-I5 -> 2661 | G6: =$B$53/$I$53*(F6) -> 1.9715043 | H6: =$B$53/SQRT($I$53)*(SQRT(I6)-SQRT(I5)) -> 1.4206801 | I6: =D6 -> 35134 | J6: =E6 -> 3100000 | K6: =J6*'Inflation Rates by Year'!$C$2 -> 3505356 | L6: =K6/I6 -> 99.771048
A7: 07-21-21 | B7: 6 | C7: Undetermined | D7: 38671 | E7: 3500000 | F7: =I7-I6 -> 3537 | G7: =$B$53/$I$53*(F7) -> 2.6205226 | H7: =$B$53/SQRT($I$53)*(SQRT(I7)-SQRT(I6)) -> 1.8075073 | I7: =D7 -> 38671 | J7: =E7 -> 3500000 | K7: =J7*'Inflation Rates by Year'!$C$2 -> 3957660 | L7: =K7/I7 -> 102.34181
A8: 07-22-21 | B8: 7 | C8: Undetermined | D8: 40877 | E8: 3800000 | F8: =I8-I7 -> 2206 | G8: =$B$53/$I$53*(F8) -> 1.6344 | H8: =$B$53/SQRT($I$53)*(SQRT(I8)-SQRT(I7)) -> 1.0856647 | I8: =D8 -> 40877 | J8: =E8 -> 3800000 | K8: =J8*'Inflation Rates by Year'!$C$2 -> 4296888 | L8: =K8/I8 -> 105.1175
A9: 07-23-21 | B9: 8 | C9: Undetermined | D9: 42785 | E9: 5000000 | F9: =I9-I8 -> 1908 | G9: =$B$53/$I$53*(F9) -> 1.4136153 | H9: =$B$53/SQRT($I$53)*(SQRT(I9)-SQRT(I8)) -> 0.91559959 | I9: =D9 -> 42785 | J9: =E9 -> 5000000 | K9: =J9*'Inflation Rates by Year'!$C$2 -> 5653800 | L9: =K9/I9 -> 132.14444
A10: 07-24-21 | B10: 9 | C10: Undetermined | D10: 43739 | E10: 6200000 | F10: =I10-I9 -> 954 | G10: =$B$53/$I$53*(F10) -> 0.70680763 | H10: =$B$53/SQRT($I$53)*(SQRT(I10)-SQRT(I9)) -> 0.45014225 | I10: =D10 -> 43739 | J10: =E10 -> 6200000 | K10: =J10*'Inflation Rates by Year'!$C$2 -> 7010712 | L10: =K10/I10 -> 160.28515
A11: 07-25-21 | B11: 10 | C11: Undetermined | D11: 44100 | E11: 7600000 | F11: =I11-I10 -> 361 | G11: =$B$53/$I$53*(F11) -> 0.26746075 | H11: =$B$53/SQRT($I$53)*(SQRT(I11)-SQRT(I10)) -> 0.16905481 | I11: =D11 -> 44100 | J11: =E11 -> 7600000 | K11: =J11*'Inflation Rates by Year'!$C$2 -> 8593776 | L11: =K11/I11 -> 194.8702
A12: 07-26-21 | B12: 11 | C12: Undetermined | D12: 51153 | E12: 8400000 | F12: =I12-I11 -> 7053 | G12: =$B$53/$I$53*(F12) -> 5.2254866 | H12: =$B$53/SQRT($I$53)*(SQRT(I12)-SQRT(I11)) -> 3.1739195 | I12: =D12 -> 51153 | J12: =E12 -> 8400000 | K12: =J12*'Inflation Rates by Year'!$C$2 -> 9498384 | L12: =K12/I12 -> 185.68577
A13: 07-27-21 | B13: 12 | C13: Undetermined | D13: 52832 | E13: 9100000 | F13: =I13-I12 -> 1679 | G13: =$B$53/$I$53*(F13) -> 1.2439518 | H13: =$B$53/SQRT($I$53)*(SQRT(I13)-SQRT(I12)) -> 0.72267429 | I13: =D13 -> 52832 | J13: =E13 -> 9100000 | K13: =J13*'Inflation Rates by Year'!$C$2 -> 10289916 | L13: =K13/I13 -> 194.76673
A14: 07-28-21 | B14: 13 | C14: Undetermined | D14: 53277 | E14: 10200000 | F14: =I14-I13 -> 445 | G14: =$B$53/$I$53*(F14) -> 0.32969538 | H14: =$B$53/SQRT($I$53)*(SQRT(I14)-SQRT(I13)) -> 0.1896042 | I14: =D14 -> 53277 | J14: =E14 -> 10200000 | K14: =J14*'Inflation Rates by Year'!$C$2 -> 11533752 | L14: =K14/I14 -> 216.48651
... A73: 09-26-21 | B73: 72 | C73: Undetermined | D73: 70168 | E73: 27788529 | F73: =I73-I72 -> 0 | G73: =$B$53/$I$53*(F73) -> 0 | H73: =$B$53/SQRT($I$53)*(SQRT(I73)-SQRT(I72)) -> 0 | I73: =D73 -> 70168 | J73: =E73 -> 27788529 | K73: =J73*'Inflation Rates by Year'!$C$2 -> 31422157 | L73: =K73/I73 -> 447.81321

Sheet BackboneLF(37)
A1: Date | B1: Fire Day | C1: Cause | D1: Acres | E1: Cost | F1: growth | G1: As | H1: Ls | I1: Best | J1: ICS 209 Cost | K1: Real Cost (Adjusted for Inflation) | L1: Cost per day per acre
A2: 06-17-21 | B2: 1 | C2: Lightning/Natural | D2: 7000 | E2: 500000 | F2: =I2-0 -> 7000 | G2: =$B$9/$I$9*(F2) -> 1.3711711 | H2: =$B$9/SQRT($I$9)*(SQRT(I3)-SQRT(I2)) -> 1.8684735 | I2: =D2 -> 7000 | J2: =E2 -> 500000 | K2: =J2*'Inflation Rates by Year'!$C$2 -> 565380 | L2: =K2/I2 -> 80.768571
A3: 06-18-21 | B3: 2 | C3: Lightning/Natural | D3: 17126 | E3: 750000 | F3: =I3-I2 -> 10126 | G3: =$B$9/$I$9*(F3) -> 1.983497 | H3: =$B$9/SQRT($I$9)*(SQRT(I3)-SQRT(I2)) -> 1.8684735 | I3: =D3 -> 17126 | J3: =E3 -> 750000 | K3: =J3*'Inflation Rates by Year'!$C$2 -> 848070 | L3: =K3/I3 -> 49.519444
A4: 06-19-21 | B4: 3 | C4: Lightning/Natural | D4: 24192 | E4: 1781330 | F4: =I4-I3 -> 7066 | G4: =$B$9/$I$9*(F4) -> 1.3840993 | H4: =$B$9/SQRT($I$9)*(SQRT(I4)-SQRT(I3)) -> 0.97664375 | I4: =D4 -> 24192 | J4: =E4 -> 1781330 | K4: =J4*'Inflation Rates by Year'!$C$2 -> 2014256.7 | L4: =K4/I4 -> 83.261273
A5: 06-20-21 | B5: 4 | C5: Lightning/Natural | D5: 34180 | E5: 2559522 | F5: =I5-I4 -> 9988 | G5: =$B$9/$I$9*(F5) -> 1.9564653 | H5: =$B$9/SQRT($I$9)*(SQRT(I5)-SQRT(I4)) -> 1.161476 | I5: =D5 -> 34180 | J5: =E5 -> 2559522 | K5: =J5*'Inflation Rates by Year'!$C$2 -> 2894205.1 | L5: =K5/I5 -> 84.675398
A6: 06-21-21 | B6: 5 | C6: Lightning/Natural | D6: 38321 | E6: 4594239 | F6: =I6-I5 -> 4141 | G6: =$B$9/$I$9*(F6) -> 0.81114566 | H6: =$B$9/SQRT($I$9)*(SQRT(I6)-SQRT(I5)) -> 0.43066279 | I6: =D6 -> 38321 | J6: =E6 -> 4594239 | K6: =J6*'Inflation Rates by Year'!$C$2 -> 5194981.7 | L6: =K6/I6 -> 135.56488
A7: 06-22-21 | B7: 6 | C7: Lightning/Natural | D7: 38321 | E7: 6428143 | F7: =I7-I6 -> 0 | G7: =$B$9/$I$9*(F7) -> 0 | H7: =$B$9/SQRT($I$9)*(SQRT(I7)-SQRT(I6)) -> 0 | I7: =D7 -> 38321 | J7: =E7 -> 6428143 | K7: =J7*'Inflation Rates by Year'!$C$2 -> 7268687 | L7: =K7/I7 -> 189.67895
A8: 06-23-21 | B8: 7 | C8: Lightning/Natural | D8: 40619 | E8: 7665718 | F8: =I8-I7 -> 2298 | G8: =$B$9/$I$9*(F8) -> 0.45013589 | H8: =$B$9/SQRT($I$9)*(SQRT(I8)-SQRT(I7)) -> 0.22896773 | I8: =D8 -> 40619 | J8: =E8 -> 7665718 | K8: =J8*'Inflation Rates by Year'!$C$2 -> 8668087.3 | L8: =K8/I8 -> 213.39982
A9: 06-24-21 | B9: 8 | C9: Lightning/Natural | D9: 40841 | E9: 8971401 | F9: =I9-I8 -> 222 | G9: =$B$9/$I$9*(F9) -> 0.043485713 | H9: =$B$9/SQRT($I$9)*(SQRT(I9)-SQRT(I8)) -> 0.021772484 | I9: =D9 -> 40841 | J9: =E9 -> 8971401 | K9: =J9*'Inflation Rates by Year'!$C$2 -> 10144501 | L9: =K9/I9 -> 248.39013
A10: 06-25-21 | B10: 9 | C10: Lightning/Natural | D10: 40855 | E10: 9969724 | F10: =I10-I9 -> 14 | G10: =$B$9/$I$9*(F10) -> 0.0027423423 | H10: =$B$9/SQRT($I$9)*(SQRT(I10)-SQRT(I9)) -> 0.0013710536 | I10: =D10 -> 40855 | J10: =E10 -> 9969724 | K10: =J10*'Inflation Rates by Year'!$C$2 -> 11273365 | L10: =K10/I10 -> 275.936
A11: 06-26-21 | B11: 10 | C11: Lightning/Natural | D11: 40855 | E11: 10997635 | F11: =I11-I10 -> 0 | G11: =$B$9/$I$9*(F11) -> 0 | H11: =$B$9/SQRT($I$9)*(SQRT(I11)-SQRT(I10)) -> 0 | I11: =D11 -> 40855 | J11: =E11 -> 10997635 | K11: =J11*'Inflation Rates by Year'!$C$2 -> 12435686 | L11: =K11/I11 -> 304.3859
A12: 06-27-21 | B12: 11 | C12: Lightning/Natural | D12: 40855 | E12: 11936360 | F12: =I12-I11 -> 0 | G12: =$B$9/$I$9*(F12) -> 0 | H12: =$B$9/SQRT($I$9)*(SQRT(I12)-SQRT(I11)) -> 0 | I12: =D12 -> 40855 | J12: =E12 -> 11936360 | K12: =J12*'Inflation Rates by Year'!$C$2 -> 13497158 | L12: =K12/I12 -> 330.36736
A13: 06-28-21 | B13: 12 | C13: Lightning/Natural | D13: 40855 | E13: 12797821 | F13: =I13-I12 -> 0 | G13: =$B$9/$I$9*(F13) -> 0 | H13: =$B$9/SQRT($I$9)*(SQRT(I13)-SQRT(I12)) -> 0 | I13: =D13 -> 40855 | J13: =E13 -> 12797821 | K13: =J13*'Inflation Rates by Year'!$C$2 -> 14471264 | L13: =K13/I13 -> 354.21036
A14: 06-29-21 | B14: 13 | C14: Lightning/Natural | D14: 40855 | E14: 13071028 | F14: =I14-I13 -> 0 | G14: =$B$9/$I$9*(F14) -> 0 | H14: =$B$9/SQRT($I$9)*(SQRT(I14)-SQRT(I13)) -> 0 | I14: =D14 -> 40855 | J14: =E14 -> 13071028 | K14: =J14*'Inflation Rates by Year'!$C$2 -> 14780196 | L14: =K14/I14 -> 361.77201
... A16: 07-14-21 | B16: 15 | C16: Lightning/Natural | D16: 40855 | E16: 13200000 | F16: =I16-I15 -> 0 | G16: =$B$9/$I$9*(F16) -> 0 | H16: =$B$9/SQRT($I$9)*(SQRT(I16)-SQRT(I15)) -> 0 | I16: =D16 -> 40855 | J16: =E16 -> 13200000 | K16: =J16*'Inflation Rates by Year'!$C$2 -> 14926032 | L16: =K16/I16 -> 365.34162

Sheet CooksPeakLF(36)
A1: Date | B1: Fire Day | C1: Cause | D1: Acres | E1: Cost | F1: growth | G1: As | H1: Ls | I1: Best | J1: ICS 209 Cost | K1: Real Cost (Adjusted for Inflation) | L1: Cost per day per acre
A2: 04-17-22 | B2: 1 | C2: Undetermined | D2: 2209 | E2: 125000 | F2: =I2-0 -> 2209 | G2: =$B$17/$I$17*(F2) -> 0.59542782 | H2: =$B$17/SQRT($I$17)*(SQRT(I2)-SQRT(0)) -> 3.0865588 | I2: =D2 -> 2209 | J2: =E2 -> 125000 | K2: =J2*'Inflation Rates by Year'!$C$2 -> 141345 | L2: =K2/I2 -> 63.985967
A3: 04-18-22 | B3: 2 | C3: Undetermined | D3: 3500 | E3: 147187 | F3: =I3-I2 -> 1291 | G3: =$B$17/$I$17*(F3) -> 0.3479843 | H3: =$B$17/SQRT($I$17)*(SQRT(I3)-SQRT(I2)) -> 0.79861739 | I3: =D3 -> 3500 | J3: =E3 -> 147187 | K3: =J3*'Inflation Rates by Year'!$C$2 -> 166433.17 | L3: =K3/I3 -> 47.552335
A4: 04-19-22 | B4: 3 | C4: Undetermined | D4: 21000 | E4: 461000 | F4: =I4-I3 -> 17500 | G4: =$B$17/$I$17*(F4) -> 4.7170606 | H4: =$B$17/SQRT($I$17)*(SQRT(I4)-SQRT(I3)) -> 5.631523 | I4: =D4 -> 21000 | J4: =E4 -> 461000 | K4: =J4*'Inflation Rates by Year'!$C$2 -> 521280.36 | L4: =K4/I4 -> 24.822874
A5: 04-20-22 | B5: 4 | C5: Undetermined | D5: 23000 | E5: 1200000 | F5: =I5-I4 -> 2000 | G5: =$B$17/$I$17*(F5) -> 0.53909264 | H5: =$B$17/SQRT($I$17)*(SQRT(I5)-SQRT(I4)) -> 0.44287137 | I5: =D5 -> 23000 | J5: =E5 -> 1200000 | K5: =J5*'Inflation Rates by Year'!$C$2 -> 1356912 | L5: =K5/I5 -> 58.996174
A6: 04-21-22 | B6: 5 | C6: Undetermined | D6: 28217 | E6: 2000000 | F6: =I6-I5 -> 5217 | G6: =$B$17/$I$17*(F6) -> 1.4062232 | H6: =$B$17/SQRT($I$17)*(SQRT(I6)-SQRT(I5)) -> 1.0718671 | I6: =D6 -> 28217 | J6: =E6 -> 2000000 | K6: =J6*'Inflation Rates by Year'!$C$2 -> 2261520 | L6: =K6/I6 -> 80.147429
A7: 04-22-22 | B7: 6 | C7: Undetermined | D7: 48672 | E7: 1800000 | F7: =I7-I6 -> 20455 | G7: =$B$17/$I$17*(F7) -> 5.51357 | H7: =$B$17/SQRT($I$17)*(SQRT(I7)-SQRT(I6)) -> 3.4568244 | I7: =D7 -> 48672 | J7: =E7 -> 1800000 | K7: =J7*'Inflation Rates by Year'!$C$2 -> 2035368 | L7: =K7/I7 -> 41.818047
A8: 04-23-22 | B8: 7 | C8: Undetermined | D8: 51982 | E8: 3200000 | F8: =I8-I7 -> 3310 | G8: =$B$17/$I$17*(F8) -> 0.89219832 | H8: =$B$17/SQRT($I$17)*(SQRT(I8)-SQRT(I7)) -> 0.48454365 | I8: =D8 -> 51982 | J8: =E8 -> 3200000 | K8: =J8*'Inflation Rates by Year'!$C$2 -> 3618432 | L8: =K8/I8 -> 69.609326
A9: 04-24-22 | B9: 8 | C9: Undetermined | D9: 54021 | E9: 4100000 | F9: =I9-I8 -> 2039 | G9: =$B$17/$I$17*(F9) -> 0.54960495 | H9: =$B$17/SQRT($I$17)*(SQRT(I9)-SQRT(I8)) -> 0.29083049 | I9: =D9 -> 54021 | J9: =E9 -> 4100000 | K9: =J9*'Inflation Rates by Year'!$C$2 -> 4636116 | L9: =K9/I9 -> 85.820625
A10: 04-25-22 | B10: 9 | C10: Undetermined | D10: 55172 | E10: 4900000 | F10: =I10-I9 -> 1151 | G10: =$B$17/$I$17*(F10) -> 0.31024781 | H10: =$B$17/SQRT($I$17)*(SQRT(I10)-SQRT(I9)) -> 0.16175051 | I10: =D10 -> 55172 | J10: =E10 -> 4900000 | K10: =J10*'Inflation Rates by Year'!$C$2 -> 5540724 | L10: =K10/I10 -> 100.42638
A11: 04-26-22 | B11: 10 | C11: Undetermined | D11: 55199 | E11: 5600000 | F11: =I11-I10 -> 27 | G11: =$B$17/$I$17*(F11) -> 0.0072777506 | H11: =$B$17/SQRT($I$17)*(SQRT(I11)-SQRT(I10)) -> 0.0037739659 | I11: =D11 -> 55199 | J11: =E11 -> 5600000 | K11: =J11*'Inflation Rates by Year'!$C$2 -> 6332256 | L11: =K11/I11 -> 114.71686
A12: 04-27-22 | B12: 11 | C12: Undetermined | D12: 55931 | E12: 6400000 | F12: =I12-I11 -> 732 | G12: =$B$17/$I$17*(F12) -> 0.19730791 | H12: =$B$17/SQRT($I$17)*(SQRT(I12)-SQRT(I11)) -> 0.10196696 | I12: =D12 -> 55931 | J12: =E12 -> 6400000 | K12: =J12*'Inflation Rates by Year'!$C$2 -> 7236864 | L12: =K12/I12 -> 129.38914
A13: 04-28-22 | B13: 12 | C13: Undetermined | D13: 55978 | E13: 7200000 | F13: =I13-I12 -> 47 | G13: =$B$17/$I$17*(F13) -> 0.012668677 | H13: =$B$17/SQRT($I$17)*(SQRT(I13)-SQRT(I12)) -> 0.0065241969 | I13: =D13 -> 55978 | J13: =E13 -> 7200000 | K13: =J13*'Inflation Rates by Year'!$C$2 -> 8141472 | L13: =K13/I13 -> 145.44057
A14: 04-29-22 | B14: 13 | C14: Undetermined | D14: 59063 | E14: 7900000 | F14: =I14-I13 -> 3085 | G14: =$B$17/$I$17*(F14) -> 0.8315504 | H14: =$B$17/SQRT($I$17)*(SQRT(I14)-SQRT(I13)) -> 0.42240553 | I14: =D14 -> 59063 | J14: =E14 -> 7900000 | K14: =J14*'Inflation Rates by Year'!$C$2 -> 8933004 | L14: =K14/I14 -> 151.24535
... A17: 05-02-22 | B17: 16 | C17: Undetermined | D17: 59359 | E17: 9700000 | F17: =I17-I16 -> 283 | G17: =$B$17/$I$17*(F17) -> 0.076281609 | H17: =$B$17/SQRT($I$17)*(SQRT(I17)-SQRT(I16)) -> 0.038186373 | I17: =D17 -> 59359 | J17: =E17 -> 9700000 | K17: =J17*'Inflation Rates by Year'!$C$2 -> 10968372 | L17: =K17/I17 -> 184.78027
A18: 05-03-22 | B18: 17 | C18: Undetermined | D18: 59359 | E18: 10100000 | F18: =I18-I17 -> 0 | G18: =$B$17/$I$17*(F18) -> 0 | H18: =$B$9/SQRT($I$9)*(SQRT(I18)-SQRT(I17)) -> 0 | I18: =D18 -> 59359 | J18: =E18 -> 10100000 | K18: =J18*'Inflation Rates by Year'!$C$2 -> 11420676 | L18: =K18/I18 -> 192.40007
A19: 05-04-22 | B19: 18 | C19: Undetermined | D19: 59359 | E19: 10600000 | F19: =I19-I18 -> 0 | G19: =$B$17/$I$17*(F19) -> 0 | H19: =$B$9/SQRT($I$9)*(SQRT(I19)-SQRT(I18)) -> 0 | I19: =D19 -> 59359 | J19: =E19 -> 10600000 | K19: =J19*'Inflation Rates by Year'!$C$2 -> 11986056 | L19: =K19/I19 -> 201.92483
A20: 05-13-22 | B20: 19 | C20: Undetermined | D20: 59359 | E20: 12500000 | F20: =I20-I19 -> 0 | G20: =$B$17/$I$17*(F20) -> 0 | H20: =$B$9/SQRT($I$9)*(SQRT(I20)-SQRT(I19)) -> 0 | I20: =D20 -> 59359 | J20: =E20 -> 12500000 | K20: =J20*'Inflation Rates by Year'!$C$2 -> 14134500 | L20: =K20/I20 -> 238.1189
A21: 05-31-22 | B21: 20 | C21: Undetermined | D21: 59359 | E21: 12500000 | F21: =I21-I20 -> 0 | G21: =$B$17/$I$17*(F21) -> 0 | H21: =$B$9/SQRT($I$9)*(SQRT(I21)-SQRT(I20)) -> 0 | I21: =D21 -> 59359 | J21: =E21 -> 12500000 | K21: =J21*'Inflation Rates by Year'!$C$2 -> 14134500 | L21: =K21/I21 -> 238.1189

Sheet HirzLF(34)
A1: Date | B1: Fire Day | C1: Cause | D1: Acres | E1: Cost | F1: growth | G1: As | H1: Ls | I1: Best | J1: ICS 209 Cost | K1: Real Cost (Adjusted for Inflation) | L1: Cost per day per acre
A2: 08-09-18 | B2: 1 | C2: Human | D2: 350 | E2: 75000 | F2: =I2-0 -> 350 | G2: =$B$29/$I$29*(F2) -> 0.21235103 | H2: =$B$29/SQRT($I$29)*(SQRT(I2)-SQRT(0)) -> 2.438407 | I2: =D2 -> 350 | J2: =E2 -> 75000 | K2: =J2*'Inflation Rates by Year'!$F$2 -> 89466.397 | L2: =K2/I2 -> 255.61828
A3: 08-10-18 | B3: 2 | C3: Human | D3: 280 | E3: 120000 | F3: =I3-I2 -> -70 | G3: =$B$29/$I$29*(F3) -> -0.042470206 | H3: =$B$29/SQRT($I$29)*(SQRT(I3)-SQRT(I2)) -> -0.25742948 | I3: =D3 -> 280 | J3: =E3 -> 120000 | K3: =J3*'Inflation Rates by Year'!$F$2 -> 143146.24 | L3: =K3/I3 -> 511.23655
A4: 08-11-18 | B4: 3 | C4: Human | D4: 2030 | E4: 300000 | F4: =I4-I3 -> 1750 | G4: =$B$29/$I$29*(F4) -> 1.0617551 | H4: =$B$29/SQRT($I$29)*(SQRT(I4)-SQRT(I3)) -> 3.6914842 | I4: =D4 -> 2030 | J4: =E4 -> 300000 | K4: =J4*'Inflation Rates by Year'!$F$2 -> 357865.59 | L4: =K4/I4 -> 176.28847
A5: 08-12-18 | B5: 4 | C5: Human | D5: 3825 | E5: 1000000 | F5: =I5-I4 -> 1795 | G5: =$B$29/$I$29*(F5) -> 1.0890574 | H5: =$B$29/SQRT($I$29)*(SQRT(I5)-SQRT(I4)) -> 2.1885193 | I5: =D5 -> 3825 | J5: =E5 -> 1000000 | K5: =J5*'Inflation Rates by Year'!$F$2 -> 1192885.3 | L5: =K5/I5 -> 311.86544
A6: 08-14-18 | B6: 5 | C6: Human | D6: 5689 | E6: 2200000 | F6: =I6-I5 -> 1864 | G6: =$B$29/$I$29*(F6) -> 1.1309209 | H6: =$B$29/SQRT($I$29)*(SQRT(I6)-SQRT(I5)) -> 1.7698481 | I6: =D6 -> 5689 | J6: =E6 -> 2200000 | K6: =J6*'Inflation Rates by Year'!$F$2 -> 2624347.6 | L6: =K6/I6 -> 461.3021
A7: 08-14-18 | B7: 6 | C7: Human | D7: 5693 | E7: 3000000 | F7: =I7-I6 -> 4 | G7: =$B$29/$I$29*(F7) -> 0.0024268689 | H7: =$B$29/SQRT($I$29)*(SQRT(I7)-SQRT(I6)) -> 0.0034554761 | I7: =D7 -> 5693 | J7: =E7 -> 3000000 | K7: =J7*'Inflation Rates by Year'!$F$2 -> 3578655.9 | L7: =K7/I7 -> 628.60634
A8: 08-15-18 | B8: 7 | C8: Human | D8: 7650 | E8: 3500000 | F8: =I8-I7 -> 1957 | G8: =$B$29/$I$29*(F8) -> 1.1873456 | H8: =$B$29/SQRT($I$29)*(SQRT(I8)-SQRT(I7)) -> 1.5656641 | I8: =D8 -> 7650 | J8: =E8 -> 3500000 | K8: =J8*'Inflation Rates by Year'!$F$2 -> 4175098.5 | L8: =K8/I8 -> 545.76451
A9: 08-17-18 | B9: 8 | C9: Human | D9: 11035 | E9: 4250000 | F9: =I9-I8 -> 3385 | G9: =$B$29/$I$29*(F9) -> 2.0537378 | H9: =$B$29/SQRT($I$29)*(SQRT(I9)-SQRT(I8)) -> 2.291782 | I9: =D9 -> 11035 | J9: =E9 -> 4250000 | K9: =J9*'Inflation Rates by Year'!$F$2 -> 5069762.5 | L9: =K9/I9 -> 459.42569
A10: 08-18-18 | B10: 9 | C10: Human | D10: 12550 | E10: 5400000 | F10: =I10-I9 -> 1515 | G10: =$B$29/$I$29*(F10) -> 0.9191766 | H10: =$B$29/SQRT($I$29)*(SQRT(I10)-SQRT(I9)) -> 0.90965397 | I10: =D10 -> 12550 | J10: =E10 -> 5400000 | K10: =J10*'Inflation Rates by Year'!$F$2 -> 6441580.6 | L10: =K10/I10 -> 513.27335
A11: 08-18-18 | B11: 10 | C11: Human | D11: 13059 | E11: 7500000 | F11: =I11-I10 -> 509 | G11: =$B$29/$I$29*(F11) -> 0.30881907 | H11: =$B$29/SQRT($I$29)*(SQRT(I11)-SQRT(I10)) -> 0.29315689 | I11: =D11 -> 13059 | J11: =E11 -> 7500000 | K11: =J11*'Inflation Rates by Year'!$F$2 -> 8946639.7 | L11: =K11/I11 -> 685.09378
A12: 08-19-18 | B12: 11 | C12: Human | D12: 14214 | E12: 8200000 | F12: =I12-I11 -> 1155 | G12: =$B$29/$I$29*(F12) -> 0.7007584 | H12: =$B$29/SQRT($I$29)*(SQRT(I12)-SQRT(I11)) -> 0.64471851 | I12: =D12 -> 14214 | J12: =E12 -> 8200000 | K12: =J12*'Inflation Rates by Year'!$F$2 -> 9781659.4 | L12: =K12/I12 -> 688.17078
A13: 08-20-18 | B13: 12 | C13: Human | D13: 15210 | E13: 9600000 | F13: =I13-I12 -> 996 | G13: =$B$29/$I$29*(F13) -> 0.60429036 | H13: =$B$29/SQRT($I$29)*(SQRT(I13)-SQRT(I12)) -> 0.53521453 | I13: =D13 -> 15210 | J13: =E13 -> 9600000 | K13: =J13*'Inflation Rates by Year'!$F$2 -> 11451699 | L13: =K13/I13 -> 752.9059
A14: 08-22-18 | B14: 13 | C14: Human | D14: 18814 | E14: 11300000 | F14: =I14-I13 -> 3604 | G14: =$B$29/$I$29*(F14) -> 2.1866089 | H14: =$B$29/SQRT($I$29)*(SQRT(I14)-SQRT(I13)) -> 1.8032709 | I14: =D14 -> 18814 | J14: =E14 -> 11300000 | K14: =J14*'Inflation Rates by Year'!$F$2 -> 13479604 | L14: =K14/I14 -> 716.46666
... A37: 09-14-18 | B37: 36 | C37: Human | D37: 46150 | E37: 55511216 | F37: =I37-I36 -> 0 | G37: =$B$29/$I$29*(F37) -> 0 | H37: =$B$29/SQRT($I$29)*(SQRT(I37)-SQRT(I36)) -> 0 | I37: =D37 -> 46150 | J37: =E37 -> 55511216 | K37: =J37*'Inflation Rates by Year'!$F$2 -> 66218513 | L37: =K37/I37 -> 1434.854

Sheet PierLF(33)
A1: Date | B1: Fire Day | C1: Cause | D1: Acres | E1: Cost | F1: growth | G1: As | H1: Ls | I1: Best | J1: ICS 209 Cost | K1: Real Cost (Adjusted for Inflation) | L1: Cost per day per acre
A2: 08-29-17 | B2: 1 | C2: Unknown | D2: 350 | E2: 1000000 | F2: =I2-0 -> 350 | G2: =$B$21/$I$21*(F2) -> 0.19148703 | H2: =$B$21/SQRT($I$21)*(SQRT(I2)-SQRT(0)) -> 1.9569723 | I2: =D2 -> 350 | J2: =E2 -> 1000000 | K2: =J2*'Inflation Rates by Year'!$G$2 -> 1217935.9 | L2: =K2/I2 -> 3479.8168
A3: 08-30-17 | B3: 2 | C3: Unknown | D3: 5289 | E3: 1300000 | F3: =I3-I2 -> 4939 | G3: =$B$21/$I$21*(F3) -> 2.7021556 | H3: =$B$21/SQRT($I$21)*(SQRT(I3)-SQRT(I2)) -> 5.6504486 | I3: =D3 -> 5289 | J3: =E3 -> 1300000 | K3: =J3*'Inflation Rates by Year'!$G$2 -> 1583316.6 | L3: =K3/I3 -> 299.3603
A4: 08-31-17 | B4: 3 | C4: Unknown | D4: 6794 | E4: 3500000 | F4: =I4-I3 -> 1505 | G4: =$B$21/$I$21*(F4) -> 0.82339424 | H4: =$B$21/SQRT($I$21)*(SQRT(I4)-SQRT(I3)) -> 1.0146866 | I4: =D4 -> 6794 | J4: =E4 -> 3500000 | K4: =J4*'Inflation Rates by Year'!$G$2 -> 4262775.6 | L4: =K4/I4 -> 627.43238
A5: 09-01-17 | B5: 4 | C5: Unknown | D5: 10311 | E5: 5300000 | F5: =I5-I4 -> 3517 | G5: =$B$21/$I$21*(F5) -> 1.9241711 | H5: =$B$21/SQRT($I$21)*(SQRT(I5)-SQRT(I4)) -> 1.9997643 | I5: =D5 -> 10311 | J5: =E5 -> 5300000 | K5: =J5*'Inflation Rates by Year'!$G$2 -> 6455060.2 | L5: =K5/I5 -> 626.03629
A6: 09-02-17 | B6: 5 | C6: Human | D6: 13240 | E6: 7900000 | F6: =I6-I5 -> 2929 | G6: =$B$21/$I$21*(F6) -> 1.6024729 | H6: =$B$21/SQRT($I$21)*(SQRT(I6)-SQRT(I5)) -> 1.4144739 | I6: =D6 -> 13240 | J6: =E6 -> 7900000 | K6: =J6*'Inflation Rates by Year'!$G$2 -> 9621693.5 | L6: =K6/I6 -> 726.71401
A7: 09-03-17 | B7: 6 | C7: Human | D7: 17418 | E7: 10000000 | F7: =I7-I6 -> 4178 | G7: =$B$21/$I$21*(F7) -> 2.2858081 | H7: =$B$21/SQRT($I$21)*(SQRT(I7)-SQRT(I6)) -> 1.76908 | I7: =D7 -> 17418 | J7: =E7 -> 10000000 | K7: =J7*'Inflation Rates by Year'!$G$2 -> 12179359 | L7: =K7/I7 -> 699.2398
A8: 09-04-17 | B8: 7 | C8: Human | D8: 20529 | E8: 12600000 | F8: =I8-I7 -> 3111 | G8: =$B$21/$I$21*(F8) -> 1.7020462 | H8: =$B$21/SQRT($I$21)*(SQRT(I8)-SQRT(I7)) -> 1.1822593 | I8: =D8 -> 20529 | J8: =E8 -> 12600000 | K8: =J8*'Inflation Rates by Year'!$G$2 -> 15345992 | L8: =K8/I8 -> 747.5275
A9: 09-05-17 | B9: 8 | C9: Human | D9: 20529 | E9: 14400000 | F9: =I9-I8 -> 0 | G9: =$B$21/$I$21*(F9) -> 0 | H9: =$B$21/SQRT($I$21)*(SQRT(I9)-SQRT(I8)) -> 0 | I9: =D9 -> 20529 | J9: =E9 -> 14400000 | K9: =J9*'Inflation Rates by Year'!$G$2 -> 17538277 | L9: =K9/I9 -> 854.31715
A10: 09-06-17 | B10: 9 | C10: Human | D10: 20864 | E10: 16300000 | F10: =I10-I9 -> 335 | G10: =$B$21/$I$21*(F10) -> 0.18328045 | H10: =$B$21/SQRT($I$21)*(SQRT(I10)-SQRT(I9)) -> 0.12179251 | I10: =D10 -> 20864 | J10: =E10 -> 16300000 | K10: =J10*'Inflation Rates by Year'!$G$2 -> 19852355 | L10: =K10/I10 -> 951.51241
A11: 09-07-17 | B11: 10 | C11: Human | D11: 24949 | E11: 18500000 | F11: =I11-I10 -> 4085 | G11: =$B$21/$I$21*(F11) -> 2.2349272 | H11: =$B$21/SQRT($I$21)*(SQRT(I11)-SQRT(I10)) -> 1.4130784 | I11: =D11 -> 24949 | J11: =E11 -> 18500000 | K11: =J11*'Inflation Rates by Year'!$G$2 -> 22531814 | L11: =K11/I11 -> 903.11491
A12: 09-08-17 | B12: 11 | C12: Human | D12: 24949 | E12: 20600000 | F12: =I12-I11 -> 0 | G12: =$B$21/$I$21*(F12) -> 0 | H12: =$B$21/SQRT($I$21)*(SQRT(I12)-SQRT(I11)) -> 0 | I12: =D12 -> 24949 | J12: =E12 -> 20600000 | K12: =J12*'Inflation Rates by Year'!$G$2 -> 25089479 | L12: =K12/I12 -> 1005.6307
A13: 09-09-17 | B13: 12 | C13: Human | D13: 26748 | E13: 22800000 | F13: =I13-I12 -> 1799 | G13: =$B$21/$I$21*(F13) -> 0.98424335 | H13: =$B$21/SQRT($I$21)*(SQRT(I13)-SQRT(I12)) -> 0.58532884 | I13: =D13 -> 26748 | J13: =E13 -> 22800000 | K13: =J13*'Inflation Rates by Year'!$G$2 -> 27768938 | L13: =K13/I13 -> 1038.1688
A14: 09-10-17 | B14: 13 | C14: Human | D14: 27586 | E14: 24800000 | F14: =I14-I13 -> 838 | G14: =$B$21/$I$21*(F14) -> 0.45847467 | H14: =$B$21/SQRT($I$21)*(SQRT(I14)-SQRT(I13)) -> 0.26592352 | I14: =D14 -> 27586 | J14: =E14 -> 24800000 | K14: =J14*'Inflation Rates by Year'!$G$2 -> 30204810 | L14: =K14/I14 -> 1094.9326
... A27: 09-23-17 | B27: 26 | C27: Human | D27: 36556 | E27: 38700000 | F27: =I27-I26 -> 0 | G27: =$B$21/$I$21*(F27) -> 0 | H27: =$B$21/SQRT($I$21)*(SQRT(I27)-SQRT(I26)) -> 0 | I27: =D27 -> 36556 | J27: =E27 -> 38700000 | K27: =J27*'Inflation Rates by Year'!$G$2 -> 47134119 | L27: =K27/I27 -> 1289.3675

Sheet IslandLF(31)
A1: Date | B1: Fire Day | C1: Cause | D1: Acres | E1: Cost | F1: growth | G1: As | H1: Ls | I1: Best | J1: ICS 209 Cost | K1: Real Cost (Adjusted for Inflation) | L1: Cost per day per acre
A2: 06-30-17 | B2: 1 | C2: Lightning/Natural | D2: 65 | E2: 3800 | F2: =I2-0 -> 65 | G2: =$B$6/$I$6*(F2) -> #DIV/0! | H2: =$B$6/SQRT($I$6)*(SQRT(I2)-SQRT(0)) -> #DIV/0! | I2: =D2 -> 65 | J2: =E2 -> 3800 | K2: =J2*'Inflation Rates by Year'!F$2 -> 4532.9641 | L2: =K2/I2 -> 69.737909
A3: 07-01-17 | B3: 2 | C3: Unknown | D3: 78 | E3: 58500 | F3: =I3-I2 -> 13 | G3: =$B$6/$I$6*(F3) -> #DIV/0! | H3: =$B$6/SQRT($I$6)*(SQRT(I3)-SQRT(I2)) -> #DIV/0! | I3: =D3 -> 78 | J3: =E3 -> 58500 | K3: =J3*'Inflation Rates by Year'!F$2 -> 69783.79 | L3: =K3/I3 -> 894.66397
A4: 07-02-17 | B4: 3 | C4: Lightning/Natural | D4: 98 | E4: 90000 | F4: =I4-I3 -> 20 | G4: =$B$6/$I$6*(F4) -> #DIV/0! | H4: =$B$6/SQRT($I$6)*(SQRT(I4)-SQRT(I3)) -> #DIV/0! | I4: =D4 -> 98 | J4: =E4 -> 90000 | K4: =J4*'Inflation Rates by Year'!F$2 -> 107359.68 | L4: =K4/I4 -> 1095.5069
A5: 07-03-17 | B5: 4 | C5: Lightning/Natural | D5: 130 | E5: 145000 | F5: =I5-I4 -> 32 | G5: =$B$6/$I$6*(F5) -> #DIV/0! | H5: =$B$6/SQRT($I$6)*(SQRT(I5)-SQRT(I4)) -> #DIV/0! | I5: =D5 -> 130 | J5: =E5 -> 145000 | K5: =J5*'Inflation Rates by Year'!F$2 -> 172968.37 | L5: =K5/I5 -> 1330.5259
A6: 07-04-17 | B6: 5 | C6: Unknown | D6: 200 | E6: 166000
A7: 07-05-17 | B7: 6 | C7: Unknown | D7: 257 | E7: 197000
A8: 07-06-17 | B8: 7 | C8: Unknown | D8: 382 | E8: 232000
A9: 07-07-17 | B9: 8 | C9: Unknown | D9: 567 | E9: 273000
A10: 07-08-17 | B10: 9 | C10: Unknown | D10: 736 | E10: 313000
A11: 07-09-17 | B11: 10 | C11: Unknown | D11: 881 | E11: 354000
A12: 07-10-17 | B12: 11 | C12: Unknown | D12: 962 | E12: 400000
A13: 07-11-17 | B13: 12 | C13: Unknown | D13: 1039 | E13: 450000
A14: 07-12-17 | B14: 13 | C14: Lightning/Natural | D14: 1069 | E14: 495000
A15: 07-13-17 | B15: 14 | C15: Lightning/Natural | D15: 1090 | E15: 540000
A16: 07-14-17 | B16: 15 | C16: Lightning/Natural | D16: 1141 | E16: 585000
A17: 07-15-17 | B17: 16 | C17: Lightning/Natural | D17: 1176 | E17: 635000
... A46: 08-13-17 | B46: 45 | C46: Lightning/Natural | D46: 13497 | E46: 50145

Sheet WhitmoreLF(32)
A1: Date | B1: Fire Day | C1: Cause | D1: Acres | E1: Cost | F1: growth | G1: As | H1: Ls | I1: Best | J1: ICS 209 Cost | K1: Real Cost (Adjusted for Inflation) | L1: Cost per day per acre
A2: 08-03-21 | B2: 1 | C2: Lightning/Natural | D2: 2000 | E2: 250000 | F2: =I2-0 -> 2000 | G2: =$B$15/$I$15*(F2) -> 0.48043926 | H2: =$B$15/SQRT($I$15)*(SQRT(I2)-SQRT(0)) -> 2.5934821 | I2: =D2 -> 2000 | J2: =E2 -> 250000 | K2: =J2*'Inflation Rates by Year'!C$2 -> 282690 | L2: =K2/I2 -> 141.345
A3: 08-04-21 | B3: 2 | C3: Lightning/Natural | D3: 4300 | E3: 495000 | F3: =I3-I2 -> 2300 | G3: =$B$15/$I$15*(F3) -> 0.55250515 | H3: =$B$15/SQRT($I$15)*(SQRT(I3)-SQRT(I2)) -> 1.2093092 | I3: =D3 -> 4300 | J3: =E3 -> 495000 | K3: =J3*'Inflation Rates by Year'!C$2 -> 559726.2 | L3: =K3/I3 -> 130.16888
A4: 08-05-21 | B4: 3 | C4: Lightning/Natural | D4: 15000 | E4: 495000 | F4: =I4-I3 -> 10700 | G4: =$B$15/$I$15*(F4) -> 2.57035 | H4: =$B$15/SQRT($I$15)*(SQRT(I4)-SQRT(I3)) -> 3.2997521 | I4: =D4 -> 15000 | J4: =E4 -> 495000 | K4: =J4*'Inflation Rates by Year'!C$2 -> 559726.2 | L4: =K4/I4 -> 37.31508
A5: 08-06-21 | B5: 4 | C5: Lightning/Natural | D5: 53314 | E5: 600000 | F5: =I5-I4 -> 38314 | G5: =$B$15/$I$15*(F5) -> 9.2037749 | H5: =$B$15/SQRT($I$15)*(SQRT(I5)-SQRT(I4)) -> 6.2877132 | I5: =D5 -> 53314 | J5: =E5 -> 600000 | K5: =J5*'Inflation Rates by Year'!C$2 -> 678456 | L5: =K5/I5 -> 12.725663
A6: 08-07-21 | B6: 5 | C6: Lightning/Natural | D6: 53314 | E6: 2000000 | F6: =I6-I5 -> 0 | G6: =$B$15/$I$15*(F6) -> 0 | H6: =$B$15/SQRT($I$15)*(SQRT(I6)-SQRT(I5)) -> 0 | I6: =D6 -> 53314 | J6: =E6 -> 2000000 | K6: =J6*'Inflation Rates by Year'!C$2 -> 2261520 | L6: =K6/I6 -> 42.418877
A7: 08-08-21 | B7: 6 | C7: D. Fire Suppression Strategy: | D7: 55970 | E7: 2650000 | F7: =I7-I6 -> 2656 | G7: =$B$15/$I$15*(F7) -> 0.63802334 | H7: =$B$15/SQRT($I$15)*(SQRT(I7)-SQRT(I6)) -> 0.3294846 | I7: =D7 -> 55970 | J7: =E7 -> 2650000 | K7: =J7*'Inflation Rates by Year'!C$2 -> 2996514 | L7: =K7/I7 -> 53.53786
A8: 08-09-21 | B8: 7 | C8: Lightning/Natural | D8: 56454 | E8: 2950000 | F8: =I8-I7 -> 484 | G8: =$B$15/$I$15*(F8) -> 0.1162663 | H8: =$B$15/SQRT($I$15)*(SQRT(I8)-SQRT(I7)) -> 0.059192968 | I8: =D8 -> 56454 | J8: =E8 -> 2950000 | K8: =J8*'Inflation Rates by Year'!C$2 -> 3335742 | L8: =K8/I8 -> 59.087788
A9: 08-10-21 | B9: 8 | C9: Lightning/Natural | D9: 57460 | E9: 5000000 | F9: =I9-I8 -> 1006 | G9: =$B$15/$I$15*(F9) -> 0.24166095 | H9: =$B$15/SQRT($I$15)*(SQRT(I9)-SQRT(I8)) -> 0.12222694 | I9: =D9 -> 57460 | J9: =E9 -> 5000000 | K9: =J9*'Inflation Rates by Year'!C$2 -> 5653800 | L9: =K9/I9 -> 98.395405
A10: 08-11-21 | B10: 9 | C10: Lightning/Natural | D10: 57478 | E10: 6100000 | F10: =I10-I9 -> 18 | G10: =$B$15/$I$15*(F10) -> 0.0043239533 | H10: =$B$15/SQRT($I$15)*(SQRT(I10)-SQRT(I9)) -> 0.0021771781 | I10: =D10 -> 57478 | J10: =E10 -> 6100000 | K10: =J10*'Inflation Rates by Year'!C$2 -> 6897636 | L10: =K10/I10 -> 120.0048
A11: 08-12-21 | B11: 10 | C11: Lightning/Natural | D11: 58087 | E11: 6850000 | F11: =I11-0 -> 58087 | G11: =$B$15/$I$15*(F11) -> 13.953638 | H11: =$B$15/SQRT($I$15)*(SQRT(I11)-SQRT(0)) -> 13.9768 | I11: =D11 -> 58087 | J11: =E11 -> 6850000 | K11: =J11*'Inflation Rates by Year'!C$2 -> 7745706 | L11: =K11/I11 -> 133.34664
A12: 08-13-21 | B12: 11 | C12: Lightning/Natural | D12: 58265 | E12: 7400000 | F12: =I12-I11 -> 178 | G12: =$B$15/$I$15*(F12) -> 0.042759094 | H12: =$B$15/SQRT($I$15)*(SQRT(I12)-SQRT(I11)) -> 0.021398655 | I12: =D12 -> 58265 | J12: =E12 -> 7400000 | K12: =J12*'Inflation Rates by Year'!C$2 -> 8367624 | L12: =K12/I12 -> 143.61322
A13: 08-14-21 | B13: 12 | C13: D. Fire Suppression Strategy: | D13: 58276 | E13: 7800000 | F13: =I13-I12 -> 11 | G13: =$B$15/$I$15*(F13) -> 0.0026424159 | H13: =$B$15/SQRT($I$15)*(SQRT(I13)-SQRT(I12)) -> 0.0013213157 | I13: =D13 -> 58276 | J13: =E13 -> 7800000 | K13: =J13*'Inflation Rates by Year'!C$2 -> 8819928 | L13: =K13/I13 -> 151.34752
A14: 08-15-21 | B14: 13 | C14: D. Fire Suppression Strategy: | D14: 58276 | E14: 8300000 | F14: =I14-I13 -> 0 | G14: =$B$15/$I$15*(F14) -> 0 | H14: =$B$15/SQRT($I$15)*(SQRT(I14)-SQRT(I13)) -> 0 | I14: =D14 -> 58276 | J14: =E14 -> 8300000 | K14: =J14*'Inflation Rates by Year'!C$2 -> 9385308 | L14: =K14/I14 -> 161.04928
A15: 08-16-21 | B15: 14 | C15: Lightning/Natural | D15: 58280 | E15: 8550000 | F15: =I15-I14 -> 4 | G15: =$B$15/$I$15*(F15) -> 0.00096087852 | H15: =$B$15/SQRT($I$15)*(SQRT(I15)-SQRT(I14)) -> 0.0004804475 | I15: =D15 -> 58280 | J15: =E15 -> 8550000 | K15: =J15*'Inflation Rates by Year'!C$2 -> 9667998 | L15: =K15/I15 -> 165.88878
A16: 08-17-21 | B16: 15 | C16: Lightning/Natural | D16: 58280 | E16: 8900000 | F16: =I16-I15 -> 0 | G16: =$B$15/$I$15*(F16) -> 0 | H16: =$B$15/SQRT($I$15)*(SQRT(I16)-SQRT(I15)) -> 0 | I16: =D16 -> 58280 | J16: =E16 -> 8900000 | K16: =J16*'Inflation Rates by Year'!C$2 -> 10063764 | L16: =K16/I16 -> 172.67955
A17: 08-18-21 | B17: 16 | C17: Lightning/Natural | D17: 58280 | E17: 9200000 | F17: =I17-I16 -> 0 | G17: =$B$15/$I$15*(F17) -> 0 | H17: =$B$15/SQRT($I$15)*(SQRT(I17)-SQRT(I16)) -> 0 | I17: =D17 -> 58280 | J17: =E17 -> 9200000 | K17: =J17*'Inflation Rates by Year'!C$2 -> 10402992 | L17: =K17/I17 -> 178.50021
A18: 08-20-21 | B18: 17 | C18: Lightning/Natural | D18: 58280 | E18: 7500000 | F18: =I18-I17 -> 0 | G18: =$B$15/$I$15*(F18) -> 0 | H18: =$B$15/SQRT($I$15)*(SQRT(I18)-SQRT(I17)) -> 0 | I18: =D18 -> 58280 | J18: =E18 -> 7500000 | K18: =J18*'Inflation Rates by Year'!C$2 -> 8480700 | L18: =K18/I18 -> 145.51647
A19: 08-21-21 | B19: 18 | C19: Undetermined | D19: 58280 | E19: 8000000 | F19: =I19-I18 -> 0 | G19: =$B$15/$I$15*(F19) -> 0 | H19: =$B$15/SQRT($I$15)*(SQRT(I19)-SQRT(I18)) -> 0 | I19: =D19 -> 58280 | J19: =E19 -> 8000000 | K19: =J19*'Inflation Rates by Year'!C$2 -> 9046080 | L19: =K19/I19 -> 155.21757
A20: 08-22-21 | B20: 19 | C20: Undetermined | D20: 57460 | E20: 7900000 | F20: =I20-0 -> 57460 | G20: =$B$15/$I$15*(F20) -> 13.80302 | H20: =$B$15/SQRT($I$15)*(SQRT(I20)-SQRT(0)) -> 13.901161 | I20: =D20 -> 57460 | J20: =E20 -> 7900000 | K20: =J20*'Inflation Rates by Year'!C$2 -> 8933004 | L20: =K20/I20 -> 155.46474
A21: 09-15-21 | B21: 20 | C21: Lightning/Natural | D21: 58280 | E21: 8000000 | F21: =I21-I20 -> 820 | G21: =$B$15/$I$15*(F21) -> 0.1969801 | H21: =$B$15/SQRT($I$15)*(SQRT(I21)-SQRT(I20)) -> 0.098838946 | I21: =D21 -> 58280 | J21: =E21 -> 8000000 | K21: =J21*'Inflation Rates by Year'!C$2 -> 9046080 | L21: =K21/I21 -> 155.21757
A22: 10-16-21 | B22: 21 | C22: Undetermined | D22: 58234 | E22: 20000000 | F22: =I22-I21 -> -46 | G22: =$B$15/$I$15*(F22) -> -0.011050103 | H22: =$B$15/SQRT($I$15)*(SQRT(I22)-SQRT(I21)) -> -0.0055261421 | I22: =D22 -> 58234 | J22: =E22 -> 20000000 | K22: =J22*'Inflation Rates by Year'!C$2 -> 22615200 | L22: =K22/I22 -> 388.35045

Sheet Road702LF(29)
A1: Date | B1: Fire Day | C1: Cause | D1: Acres | E1: Cost | F1: growth | G1: As | H1: Ls | I1: Best | J1: ICS 209 Cost | K1: Real Cost (Adjusted for Inflation) | L1: Cost per day per acre
A2: 04-22-22 | B2: 1 | C2: Undetermined | D2: 47000 | E2: 200000 | F2: =I2-0 -> 47000 | G2: =$B$7/$I$7*(F2) -> 6.4055969 | H2: =$B$7/SQRT($I$7)*(SQRT(I2)-SQRT(0)) -> 6.1994824 | I2: =D2 -> 47000 | J2: =E2 -> 200000 | K2: =J2*'Inflation Rates by Year'!F$2 -> 238577.06 | L2: =K2/I2 -> 5.0761076
A3: 04-23-22 | B3: 2 | C3: Undetermined | D3: 41155 | E3: 218204 | F3: =I3-I2 -> -5845 | G3: =$B$7/$I$7*(F3) -> -0.79661094 | H3: =$B$7/SQRT($I$7)*(SQRT(I3)-SQRT(I2)) -> -0.39828284 | I3: =D3 -> 41155 | J3: =E3 -> 218204 | K3: =J3*'Inflation Rates by Year'!F$2 -> 260292.34 | L3: =K3/I3 -> 6.3246833
A4: 04-24-22 | B4: 3 | C4: Undetermined | D4: 42425 | E4: 527027 | F4: =I4-I3 -> 1270 | G4: =$B$7/$I$7*(F4) -> 0.17308741 | H4: =$B$7/SQRT($I$7)*(SQRT(I4)-SQRT(I3)) -> 0.088829369 | I4: =D4 -> 42425 | J4: =E4 -> 527027 | K4: =J4*'Inflation Rates by Year'!F$2 -> 628682.76 | L4: =K4/I4 -> 14.818686
A5: 04-25-22 | B5: 4 | C5: Undetermined | D5: 41448 | E5: 932464 | F5: =I5-I4 -> -977 | G5: =$B$7/$I$7*(F5) -> -0.13315464 | H5: =$B$7/SQRT($I$7)*(SQRT(I5)-SQRT(I4)) -> -0.068215387 | I5: =D5 -> 41448 | J5: =E5 -> 932464 | K5: =J5*'Inflation Rates by Year'!F$2 -> 1112322.6 | L5: =K5/I5 -> 26.836581
A6: 04-26-22 | B6: 5 | C6: Undetermined | D6: 43582 | E6: 1326414 | F6: =I6-0 -> 43582 | G6: =$B$7/$I$7*(F6) -> 5.9397601 | H6: =$B$7/SQRT($I$7)*(SQRT(I6)-SQRT(I5)) -> 0.14799057 | I6: =D6 -> 43582 | J6: =E6 -> 1326414 | K6: =J6*'Inflation Rates by Year'!F$2 -> 1582259.8 | L6: =K6/I6 -> 36.30535
A7: 04-27-22 | B7: 6 | C7: Undetermined | D7: 44024 | E7: 1588135 | F7: =I7-I6 -> 442 | G7: =$B$7/$I$7*(F7) -> 0.060239869 | H7: =$B$7/SQRT($I$7)*(SQRT(I7)-SQRT(I6)) -> 0.030195917 | I7: =D7 -> 44024 | J7: =E7 -> 1588135 | K7: =J7*'Inflation Rates by Year'!F$2 -> 1894462.9 | L7: =K7/I7 -> 43.032502
A8: 04-29-22 | B8: 7 | C8: Undetermined | D8: 44024 | E8: 1800000 | F8: =I8-I7 -> 0 | G8: =$B$7/$I$7*(F8) -> 0 | H8: =$B$7/SQRT($I$7)*(SQRT(I8)-SQRT(I7)) -> 0 | I8: =D8 -> 44024 | J8: =E8 -> 1800000 | K8: =J8*'Inflation Rates by Year'!F$2 -> 2147193.5 | L8: =K8/I8 -> 48.773249
A9: 04-30-22 | B9: 8 | C9: Undetermined | D9: 44024 | E9: 1800000 | F9: =I9-I8 -> 0 | G9: =$B$7/$I$7*(F9) -> 0 | H9: =$B$7/SQRT($I$7)*(SQRT(I9)-SQRT(I8)) -> 0 | I9: =D9 -> 44024 | J9: =E9 -> 1800000 | K9: =J9*'Inflation Rates by Year'!F$2 -> 2147193.5 | L9: =K9/I9 -> 48.773249

Sheet RiverLF(42)
A1: Date | B1: Fire Day | C1: Cause | D1: Acres | E1: Cost | F1: growth | G1: As | H1: Ls | I1: Best | J1: ICS 209 Cost | K1: Real Cost (Adjusted for Inflation) | L1: Cost per day per acre
A2: 08-16-20 | B2: 1 | C2: Unknown | D2: 2000 | E2: 200000 | F2: =I2-0 -> 2000 | G2: =$B$15/$I$15*(F2) -> 0.58226585 | H2: =$B$15/SQRT($I$15)*(SQRT(I2)-SQRT(0)) -> 2.855122 | I2: =D2 -> 2000 | J2: =E2 -> 200000 | K2: =J2*'Inflation Rates by Year'!D$2 -> 228865.82 | L2: =K2/I2 -> 114.43291
A3: 08-17-20 | B3: 2 | C3: Unknown | D3: 3793 | E3: 1600000 | F3: =I3-I2 -> 1793 | G3: =$B$15/$I$15*(F3) -> 0.52200133 | H3: =$B$15/SQRT($I$15)*(SQRT(I3)-SQRT(I2)) -> 1.0767656 | I3: =D3 -> 3793 | J3: =E3 -> 1600000 | K3: =J3*'Inflation Rates by Year'!D$2 -> 1830926.6 | L3: =K3/I3 -> 482.71199
A4: 08-18-20 | B4: 3 | C4: Unknown | D4: 4509 | E4: 2239408 | F4: =I4-I3 -> 716 | G4: =$B$15/$I$15*(F4) -> 0.20845117 | H4: =$B$15/SQRT($I$15)*(SQRT(I4)-SQRT(I3)) -> 0.35507595 | I4: =D4 -> 4509 | J4: =E4 -> 2239408 | K4: =J4*'Inflation Rates by Year'!D$2 -> 2562619.8 | L4: =K4/I4 -> 568.33439
A5: 08-19-20 | B5: 4 | C5: Unknown | D5: 15050 | E5: 4396398 | F5: =I5-I4 -> 10541 | G5: =$B$15/$I$15*(F5) -> 3.0688321 | H5: =$B$15/SQRT($I$15)*(SQRT(I5)-SQRT(I4)) -> 3.5451311 | I5: =D5 -> 15050 | J5: =E5 -> 4396398 | K5: =J5*'Inflation Rates by Year'!D$2 -> 5030926.3 | L5: =K5/I5 -> 334.28081
A6: 08-20-20 | B6: 5 | C6: Unknown | D6: 39464 | E6: 7723688 | F6: =I6-I5 -> 24414 | G6: =$B$15/$I$15*(F6) -> 7.1077192 | H6: =$B$15/SQRT($I$15)*(SQRT(I6)-SQRT(I5)) -> 4.8505618 | I6: =D6 -> 39464 | J6: =E6 -> 7723688 | K6: =J6*'Inflation Rates by Year'!D$2 -> 8838441.1 | L6: =K6/I6 -> 223.96212
A7: 08-21-20 | B7: 6 | C7: Unknown | D7: 42583 | E7: 9098108 | F7: =I7-I6 -> 3119 | G7: =$B$15/$I$15*(F7) -> 0.90804359 | H7: =$B$15/SQRT($I$15)*(SQRT(I7)-SQRT(I6)) -> 0.4916513 | I7: =D7 -> 42583 | J7: =E7 -> 9098108 | K7: =J7*'Inflation Rates by Year'!D$2 -> 10411230 | L7: =K7/I7 -> 244.49264
